<?xml version="1.0" ?>
<robot name="fanuc" xmlns:xacro="http://ros.org/wiki/xacro">
    <!-- ~~~~~~~~~~~~~~ COLORS ~~~~~~~~~~~~~~ -->
    <!-- Upper links and bases -->
    <material name="white">
        <color rgba="1.0 1.0 1.0 1.0" />
    </material>
    <!-- Lower link color -->
    <material name="black">
        <color rgba="0.0 0.0 0.0 1.0" />
    </material>
    <!-- ~~~~~~~~~~~~ FIXED BASE ~~~~~~~~~~~~ -->
    <!-- World -->
    <link name="base_link" />
    <!-- Joint between world and fixed base -->
    <joint name="base" type="fixed">
        <parent link="base_link" />
        <child link="Fixed_Base" />
        <axis xyz="0 0 0" />
        <origin rpy="0 0 0" xyz="0 0 1.452" />
    </joint>
    <!-- Fixed triangular base -->
    <link name="Fixed_Base">
        <inertial>
            <origin rpy="0 0 0" xyz="0.0 0.0 0.0" />
            <mass value="0.48" />
            <inertia ixx="0.003604" ixy="0.0" ixz="0.0" iyy="0.003604" iyz="0.0" izz="0.0072" />
        </inertial>
        <visual>
            <material name="white" />
            <origin rpy="0 0 0" xyz="0 0 0" />
            <geometry>
                <mesh filename="package://fanuc/src/mesh/fixed_base.stl" scale="0.001 0.001 0.001" />
            </geometry>
        </visual>
        <collision>
            <origin rpy="0 0 0" xyz="0 0 0" />
            <geometry>
                <mesh filename="package://fanuc/src/mesh/fixed_base.stl" scale="0.001 0.001 0.001" />
            </geometry>
        </collision>
    </link>
    <!-- ~~~~~~~~~~~~~ JOINT 1 ~~~~~~~~~~~~~~ -->
    <!-- Motor on fixed base -->
    <joint name="J1_Motor" type="revolute">
        <limit effort="20" lower="-1.1" upper="0.8" velocity="1.57" />
        <origin rpy="0 0 0" xyz="-0.18 0.015 -0.085" />
        <parent link="Fixed_Base" />
        <child link="J1_Upper" />
        <axis xyz="0 1 0" />
    </joint>
    <!-- Upper link -->
    <link name="J1_Upper">
        <inertial>
            <origin rpy="0 0 0" xyz="0 -0.071 0" />
            <mass value="0.0466" />
            <inertia ixx="0.0" ixy="0.0" ixz="0.0" iyy="0.0" iyz="0.0" izz="1.94166666667e-05" />
        </inertial>
        <visual>
            <material name="white" />
            <origin rpy="3.14 0 0" xyz="0 0 0" />
            <geometry>
                <mesh filename="package://fanuc/src/mesh/upper_link.stl" scale="0.001 0.001 0.001" />
            </geometry>
        </visual>
        <collision>
            <origin rpy="3.14 0 0" xyz="0 0 0" />
            <geometry>
                <mesh filename="package://fanuc/src/mesh/upper_link.stl" scale="0.001 0.001 0.001" />
            </geometry>
        </collision>
    </link>
    <!-- Joint between fixed base and upper link -->
    <joint name="J1_Upper" type="continuous">
        <origin rpy="0 -0.637 0" xyz="-0.565 -0.01 -0.02" />
        <parent link="J1_Upper" />
        <child link="J1_Knee" />
        <axis xyz="1 0 0" />
    </joint>
    <!-- Pin between upper and lower links -->
    <link name="J1_Knee">
        <inertial>
            <origin rpy="0 1.57 1.57" xyz="0 0 0" />
            <mass value="0.0173" />
            <inertia ixx="3.60993333333e-06" ixy="0.0" ixz="0.0" iyy="3.60993333333e-06" iyz="0.0" izz="1.15333333333e-08" />
        </inertial>
        <visual>
            <material name="black" />
            <origin rpy="0 1.57 1.57" xyz="0 0 0" />
            <geometry>
                <cylinder length="0.05" radius="0.005" />
            </geometry>
        </visual>
        <collision>
            <origin rpy="0 1.57 1.57" xyz="0 0 0" />
            <geometry>
                <cylinder length="0.05" radius="0.005" />
            </geometry>
        </collision>
    </link>
    <!-- Joint between pin and left lower link -->
    <joint name="J1_Knee" type="continuous">
        <origin rpy="0 0 0" xyz="0 0 0" />
        <parent link="J1_Knee" />
        <child link="J1_Lower" />
        <axis xyz="0 1 0" />
    </joint>
    <!-- Left lower link -->
    <link name="J1_Lower">
        <inertial>
            <origin rpy="0 0 0" xyz="0 0 -0.585" />
            <mass value="0.04" />
            <inertia ixx="0.000867013333333" ixy="0.0" ixz="0.0" iyy="0.000867013333333" iyz="0.0" izz="2.66666666667e-08" />
        </inertial>
        <visual>
            <material name="black" />
            <origin rpy="0 1.57 0" xyz="0 0 -0.585" />
            <geometry>
                <box size="1.175 0.05 0.005" />
            </geometry>
        </visual>
        <collision>
            <origin rpy="0 1.57 0" xyz="0 0 -0.585" />
            <geometry>
                <box size="1.175 0.05 0.005" />
            </geometry>
        </collision>
    </link>
    <!-- Joint between pin and lower left link -->
    <joint name="J1_Ankle" type="continuous">
        <origin rpy="0 0 0" xyz="0 0 -1.175" />
        <parent link="J1_Lower" />
        <child link="J1_Ankle" />
        <axis xyz="1 0 0" />
    </joint>
    <!-- Pin between lower link and end effector -->
    <link name="J1_Ankle">
        <inertial>
            <origin rpy="0 1.57 1.57" xyz="0 0 0" />
            <mass value="0.0173" />
            <inertia ixx="3.60993333333e-06" ixy="0.0" ixz="0.0" iyy="3.60993333333e-06" iyz="0.0" izz="1.15333333333e-08" />
        </inertial>
        <visual>
            <material name="black" />
            <origin rpy="0 1.57 1.57" xyz="0 0 0" />
            <geometry>
                <cylinder length="0.05" radius="0.005" />
            </geometry>
        </visual>
        <collision>
            <origin rpy="0 1.57 1.57" xyz="0 0 0" />
            <geometry>
                <cylinder length="0.05" radius="0.005" />
            </geometry>
        </collision>
    </link>
    <!-- Joint between pin and end effector -->
    <joint name="J1_EE" type="continuous">
        <origin rpy="0 0.637 0" xyz="0.05275 0 0" />
        <parent link="J1_Ankle" />
        <child link="EE_Base" />
        <axis xyz="1 0 0" />
    </joint>
    <!-- ~~~~~~~~~~~~~ JOINT 2 ~~~~~~~~~~~~~~ -->
    <!-- Motor on fixed base-->
    <joint name="J2_Motor" type="revolute">
        <limit effort="20" lower="-1.1" upper="1.1" velocity="1.57" />
        <origin rpy="0 0 2.094" xyz="0.07725 -0.1525 -0.085" />
        <parent link="Fixed_Base" />
        <child link="J2_Upper" />
        <axis xyz="0 1 0" />
    </joint>
    <!-- Upper link -->
    <link name="J2_Upper">
        <inertial>
            <origin rpy="0 0 0" xyz="0 -0.071 0" />
            <mass value="0.0466" />
            <inertia ixx="0.0" ixy="0.0" ixz="0.0" iyy="0.0" iyz="0.0" izz="1.94166666667e-05" />
        </inertial>
        <visual>
            <material name="white" />
            <origin rpy="3.14 0 0" xyz="0 0 0" />
            <geometry>
                <mesh filename="package://fanuc/src/mesh/upper_link.stl" scale="0.001 0.001 0.001" />
            </geometry>
        </visual>
        <collision>
            <origin rpy="3.14 0 0" xyz="0 0 0" />
            <geometry>
                <mesh filename="package://fanuc/src/mesh/upper_link.stl" scale="0.001 0.001 0.001" />
            </geometry>
        </collision>
    </link>
    <!-- Joint between fixed base and upper link -->
    <joint name="J2_Upper" type="continuous">
        <origin rpy="0 -0.637 0" xyz="-0.565 -0.01 -0.02" />
        <parent link="J2_Upper" />
        <child link="J2_Knee" />
        <axis xyz="1 0 0" />
    </joint>
    <!-- Pin between upper and lower links -->
    <link name="J2_Knee">
        <inertial>
            <origin rpy="0 1.57 1.57" xyz="0 0 0" />
            <mass value="0.0173" />
            <inertia ixx="3.60993333333e-06" ixy="0.0" ixz="0.0" iyy="3.60993333333e-06" iyz="0.0" izz="1.15333333333e-08" />
        </inertial>
        <visual>
            <material name="black" />
            <origin rpy="0 1.57 1.57" xyz="0 0 0" />
            <geometry>
                <cylinder length="0.05" radius="0.005" />
            </geometry>
        </visual>
        <collision>
            <origin rpy="0 1.57 1.57" xyz="0 0 0" />
            <geometry>
                <cylinder length="0.05" radius="0.005" />
            </geometry>
        </collision>
    </link>
    <!-- Joint between pin and left lower link -->
    <joint name="J2_Knee" type="continuous">
        <origin rpy="0 0 0" xyz="0 0 0" />
        <parent link="J2_Knee" />
        <child link="J2_Lower" />
        <axis xyz="0 1 0" />
    </joint>
    <!-- Left lower link -->
    <link name="J2_Lower">
        <inertial>
            <origin rpy="0 0 0" xyz="0 0 -0.585" />
            <mass value="0.04" />
            <inertia ixx="0.000867013333333" ixy="0.0" ixz="0.0" iyy="0.000867013333333" iyz="0.0" izz="2.66666666667e-08" />
        </inertial>
        <visual>
            <material name="black" />
            <origin rpy="0 1.57 0" xyz="0 0 -0.585" />
            <geometry>
                <box size="1.175 0.05 0.005" />
            </geometry>
        </visual>
        <collision>
            <origin rpy="0 1.57 0" xyz="0 0 -0.585" />
            <geometry>
                <box size="1.175 0.05 0.005" />
            </geometry>
        </collision>
    </link>
    <!-- Joint between pin and lower left link -->
    <joint name="J2_Ankle" type="continuous">
        <origin rpy="0 0 0" xyz="0 0 -1.175" />
        <parent link="J2_Lower" />
        <child link="J2_Ankle" />
        <axis xyz="1 0 0" />
    </joint>
    <!-- Pin between lower link and end effector -->
    <link name="J2_Ankle">
        <inertial>
            <origin rpy="0 1.57 1.57" xyz="0 0 0" />
            <mass value="0.0173" />
            <inertia ixx="3.60993333333e-06" ixy="0.0" ixz="0.0" iyy="3.60993333333e-06" iyz="0.0" izz="1.15333333333e-08" />
        </inertial>
        <visual>
            <material name="black" />
            <origin rpy="0 1.57 1.57" xyz="0 0 0" />
            <geometry>
                <cylinder length="0.05" radius="0.005" />
            </geometry>
        </visual>
        <collision>
            <origin rpy="0 1.57 1.57" xyz="0 0 0" />
            <geometry>
                <cylinder length="0.05" radius="0.005" />
            </geometry>
        </collision>
    </link>
    <!-- Joint between pin and end effector -->
    <!--
  <joint name="J2_EE" type="revolute">
    <origin rpy="0 0.637 0" xyz="0.05275 0 0"/>
    <limit effort="20" lower="-1.1" upper="1.1" velocity="1.57"/>
    <parent link="J2_Ankle"/>
    <child link="EE_Base"/>
    <axis xyz="1 0 0"/>
  </joint>
  -->
    <!-- ~~~~~~~~~~~~~ JOINT 3 ~~~~~~~~~~~~~~ -->
    <!-- Motor on fixed base-->
    <joint name="J3_Motor" type="revolute">
        <origin rpy="0 0 -2.094" xyz="0.0925 0.154 -0.085" />
        <parent link="Fixed_Base" />
        <child link="J3_Upper" />
        <limit effort="20" lower="-1.1" upper="1.1" velocity="1.57" />
        <axis xyz="0 1 0" />
    </joint>
    <!-- Upper link -->
    <link name="J3_Upper">
        <inertial>
            <origin rpy="0 0 0" xyz="0 -0.071 0" />
            <mass value="0.0466" />
            <inertia ixx="0.0" ixy="0.0" ixz="0.0" iyy="0.0" iyz="0.0" izz="1.94166666667e-05" />
        </inertial>
        <visual>
            <material name="white" />
            <origin rpy="3.14 0 0" xyz="0 0 0" />
            <geometry>
                <mesh filename="package://fanuc/src/mesh/upper_link.stl" scale="0.001 0.001 0.001" />
            </geometry>
        </visual>
        <collision>
            <origin rpy="3.14 0 0" xyz="0 0 0" />
            <geometry>
                <mesh filename="package://fanuc/src/mesh/upper_link.stl" scale="0.001 0.001 0.001" />
            </geometry>
        </collision>
    </link>
    <!-- Joint between fixed base and upper link -->
    <joint name="J3_Upper" type="continuous">
        <origin rpy="0 -0.637 0" xyz="-0.565 -0.01 -0.02" />
        <parent link="J3_Upper" />
        <child link="J3_Knee" />
        <axis xyz="1 0 0" />
    </joint>
    <!-- Pin between upper and lower links -->
    <link name="J3_Knee">
        <inertial>
            <origin rpy="0 1.57 1.57" xyz="0 0 0" />
            <mass value="0.0173" />
            <inertia ixx="3.60993333333e-06" ixy="0.0" ixz="0.0" iyy="3.60993333333e-06" iyz="0.0" izz="1.15333333333e-08" />
        </inertial>
        <visual>
            <material name="black" />
            <origin rpy="0 1.57 1.57" xyz="0 0 0" />
            <geometry>
                <cylinder length="0.05" radius="0.005" />
            </geometry>
        </visual>
        <collision>
            <origin rpy="0 1.57 1.57" xyz="0 0 0" />
            <geometry>
                <cylinder length="0.05" radius="0.005" />
            </geometry>
        </collision>
    </link>
    <!-- Joint between pin and left lower link -->
    <joint name="J3_Knee" type="continuous">
        <origin rpy="0 0 0" xyz="0 0 0" />
        <parent link="J3_Knee" />
        <child link="J3_Lower" />
        <axis xyz="0 1 0" />
    </joint>
    <!-- Left lower link -->
    <link name="J3_Lower">
        <inertial>
            <origin rpy="0 0 0" xyz="0 0 -0.585" />
            <mass value="0.04" />
            <inertia ixx="0.000867013333333" ixy="0.0" ixz="0.0" iyy="0.000867013333333" iyz="0.0" izz="2.66666666667e-08" />
        </inertial>
        <visual>
            <material name="black" />
            <origin rpy="0 1.57 0" xyz="0 0 -0.585" />
            <geometry>
                <box size="1.175 0.05 0.005" />
            </geometry>
        </visual>
        <collision>
            <origin rpy="0 1.57 0" xyz="0 0 -0.585" />
            <geometry>
                <box size="1.175 0.05 0.005" />
            </geometry>
        </collision>
    </link>
    <!-- Joint between pin and lower left link -->
    <joint name="J3_Ankle" type="continuous">
        <origin rpy="0 0 0" xyz="0 0 -1.175" />
        <parent link="J3_Lower" />
        <child link="J3_Ankle" />
        <axis xyz="1 0 0" />
    </joint>
    <!-- Pin between lower link and end effector -->
    <link name="J3_Ankle">
        <inertial>
            <origin rpy="0 1.57 1.57" xyz="0 0 0" />
            <mass value="0.0173" />
            <inertia ixx="3.60993333333e-06" ixy="0.0" ixz="0.0" iyy="3.60993333333e-06" iyz="0.0" izz="1.15333333333e-08" />
        </inertial>
        <visual>
            <material name="black" />
            <origin rpy="0 1.57 1.57" xyz="0 0 0" />
            <geometry>
                <cylinder length="0.05" radius="0.005" />
            </geometry>
        </visual>
        <collision>
            <origin rpy="0 1.57 1.57" xyz="0 0 0" />
            <geometry>
                <cylinder length="0.05" radius="0.005" />
            </geometry>
        </collision>
    </link>
    <!-- Joint between pin and end effector -->
    <!--
  <joint name="J3_EE" type="revolute">
    <origin rpy="0 0.637 0" xyz="0 0 0"/>
    <limit effort="20" lower="-1.1" upper="1.1" velocity="1.57"/>
    <parent link="J3_Ankle"/>
    <child link="EE_Base"/>
    <axis xyz="1 0 0"/>
  </joint>
  -->
    <!-- ~~~~~~~~~~~ END EFFECTOR ~~~~~~~~~~~ -->
    <!-- End effector base-->
    <link name="EE_Base">
        <inertial>
            <origin rpy="0 0 -1.04" xyz="0 0 -0.104" />
            <mass value="0.014" />
            <inertia ixx="4.5e-06" ixy="0.0" ixz="0.0" iyy="4.5e-06" iyz="0.0" izz="4.5e-06" />
        </inertial>
        <visual>
            <material name="white" />
            <origin rpy="0 0 -1.04" xyz="0 0 -0.104" />
            <geometry>
                <mesh filename="package://fanuc/src/mesh/end_effector.stl" scale="0.001 0.001 0.001" />
            </geometry>
        </visual>
        <collision>
            <origin rpy="0 0 -1.04" xyz="0 0 -0.104" />
            <geometry>
                <mesh filename="package://fanuc/src/mesh/end_effector.stl" scale="0.001 0.001 0.001" />
            </geometry>
        </collision>
    </link>
    <!-- ~~~~~~~~~~ TRANSMISSION ~~~~~~~~~~~~ -->
    <!-- Joint 1 -->
    <transmission name="J1_Trans">
        <type>transmission_interface/SimpleTransmission</type>
        <joint name="J1_Motor">
            <hardwareInterface>hardware_interface/PositionJointInterface</hardwareInterface>
        </joint>
        <actuator name="J1_Actuator">
            <mechanicalReduction>1</mechanicalReduction>
            <hardwareInterface>hardware_interface/PositionJointInterface</hardwareInterface>
        </actuator>
    </transmission>
    <!-- Joint 2 -->
    <transmission name="J2_Trans">
        <type>transmission_interface/SimpleTransmission</type>
        <joint name="J2_Motor">
            <hardwareInterface>hardware_interface/PositionJointInterface</hardwareInterface>
        </joint>
        <actuator name="J2_Actuator">
            <mechanicalReduction>1</mechanicalReduction>
            <hardwareInterface>hardware_interface/PositionJointInterface</hardwareInterface>
        </actuator>
    </transmission>
    <!-- Joint 3 -->
    <transmission name="J3_Trans">
        <type>transmission_interface/SimpleTransmission</type>
        <joint name="J3_Motor">
            <hardwareInterface>hardware_interface/PositionJointInterface</hardwareInterface>
        </joint>
        <actuator name="J3_Actuator">
            <mechanicalReduction>1</mechanicalReduction>
            <hardwareInterface>hardware_interface/PositionJointInterface</hardwareInterface>
        </actuator>
    </transmission>
    <transmission name="trans_J1_Upper">
        <type>transmission_interface/SimpleTransmission</type>
        <joint name="J1_Upper">
            <hardwareInterface>hardware_interface/EffortJointInterface</hardwareInterface>
        </joint>
        <actuator name="J1_Upper_motor">
            <hardwareInterface>hardware_interface/EffortJointInterface</hardwareInterface>
            <mechanicalReduction>1</mechanicalReduction>
        </actuator>
    </transmission>
    <transmission name="trans_J1_Knee">
        <type>transmission_interface/SimpleTransmission</type>
        <joint name="J1_Knee">
            <hardwareInterface>hardware_interface/EffortJointInterface</hardwareInterface>
        </joint>
        <actuator name="J1_Knee_motor">
            <hardwareInterface>hardware_interface/EffortJointInterface</hardwareInterface>
            <mechanicalReduction>1</mechanicalReduction>
        </actuator>
    </transmission>
    <transmission name="trans_J1_Ankle">
        <type>transmission_interface/SimpleTransmission</type>
        <joint name="J1_Ankle">
            <hardwareInterface>hardware_interface/EffortJointInterface</hardwareInterface>
        </joint>
        <actuator name="J1_Ankle_motor">
            <hardwareInterface>hardware_interface/EffortJointInterface</hardwareInterface>
            <mechanicalReduction>1</mechanicalReduction>
        </actuator>
    </transmission>
    <transmission name="trans_J1_EE">
        <type>transmission_interface/SimpleTransmission</type>
        <joint name="J1_EE">
            <hardwareInterface>hardware_interface/EffortJointInterface</hardwareInterface>
        </joint>
        <actuator name="J1_EE_motor">
            <hardwareInterface>hardware_interface/EffortJointInterface</hardwareInterface>
            <mechanicalReduction>1</mechanicalReduction>
        </actuator>
    </transmission>
    <transmission name="trans_J2_Upper">
        <type>transmission_interface/SimpleTransmission</type>
        <joint name="J2_Upper">
            <hardwareInterface>hardware_interface/EffortJointInterface</hardwareInterface>
        </joint>
        <actuator name="J2_Upper_motor">
            <hardwareInterface>hardware_interface/EffortJointInterface</hardwareInterface>
            <mechanicalReduction>1</mechanicalReduction>
        </actuator>
    </transmission>
    <transmission name="trans_J2_Knee">
        <type>transmission_interface/SimpleTransmission</type>
        <joint name="J2_Knee">
            <hardwareInterface>hardware_interface/EffortJointInterface</hardwareInterface>
        </joint>
        <actuator name="J2_Knee_motor">
            <hardwareInterface>hardware_interface/EffortJointInterface</hardwareInterface>
            <mechanicalReduction>1</mechanicalReduction>
        </actuator>
    </transmission>
    <transmission name="trans_J2_Ankle">
        <type>transmission_interface/SimpleTransmission</type>
        <joint name="J2_Ankle">
            <hardwareInterface>hardware_interface/EffortJointInterface</hardwareInterface>
        </joint>
        <actuator name="J2_Ankle_motor">
            <hardwareInterface>hardware_interface/EffortJointInterface</hardwareInterface>
            <mechanicalReduction>1</mechanicalReduction>
        </actuator>
    </transmission>
    <transmission name="trans_J3_Upper">
        <type>transmission_interface/SimpleTransmission</type>
        <joint name="J3_Upper">
            <hardwareInterface>hardware_interface/EffortJointInterface</hardwareInterface>
        </joint>
        <actuator name="J3_Upper_motor">
            <hardwareInterface>hardware_interface/EffortJointInterface</hardwareInterface>
            <mechanicalReduction>1</mechanicalReduction>
        </actuator>
    </transmission>
    <transmission name="trans_J3_Knee">
        <type>transmission_interface/SimpleTransmission</type>
        <joint name="J3_Knee">
            <hardwareInterface>hardware_interface/EffortJointInterface</hardwareInterface>
        </joint>
        <actuator name="J3_Knee_motor">
            <hardwareInterface>hardware_interface/EffortJointInterface</hardwareInterface>
            <mechanicalReduction>1</mechanicalReduction>
        </actuator>
    </transmission>
    <transmission name="trans_J3_Ankle">
        <type>transmission_interface/SimpleTransmission</type>
        <joint name="J3_Ankle">
            <hardwareInterface>hardware_interface/EffortJointInterface</hardwareInterface>
        </joint>
        <actuator name="J3_Ankle_motor">
            <hardwareInterface>hardware_interface/EffortJointInterface</hardwareInterface>
            <mechanicalReduction>1</mechanicalReduction>
        </actuator>
    </transmission>
    <gazebo>
        <plugin name="gazebo_ros_control" filename="libgazebo_ros_control.so">
            <robotNamespace>/</robotNamespace>
        </plugin>
    </gazebo>
</robot>

