<?xml version="1.0" ?>
<<<<<<< HEAD
<!-- =================================================================================== -->
<!-- |    This document was autogenerated by xacro from m430ia.xacro                   | -->
<!-- |    EDITING THIS FILE BY HAND IS NOT RECOMMENDED                                 | -->
<!-- =================================================================================== -->
<robot name="fanuc_m430ia">
  <!-- links: main serial chain -->
=======
<robot name="fanuc_m430ia">

  <!-- ~~~~~~~~~~~~~ COLORS ~~~~~~~~~~~~~~ -->

  <material name="fanuc_grey">
    <color rgba="0.34 0.35 0.36 1.0"/>  
  </material> 


  <!-- ~~~~~~~~~~~~~ JOINTS ~~~~~~~~~~~~~~ -->


>>>>>>> 516daff7858fdc1e2262ddd0c2bcfce5399bf9be
  <link name="base_link">
    <visual>
      <origin rpy="0 0 0" xyz="0 0 0"/>
      <geometry>
        <mesh filename="package://fanuc_m430ia_support/meshes/m430ia/visual/base_link.stl"/>
      </geometry>
<<<<<<< HEAD
      <material name="">
        <color rgba="0.86 0.85 0.81 1.0"/>
      </material>
=======
      <material name="fanuc_grey"/>
>>>>>>> 516daff7858fdc1e2262ddd0c2bcfce5399bf9be
    </visual>
    <collision>
      <origin rpy="0 0 0" xyz="0 0 0"/>
      <geometry>
        <mesh filename="package://fanuc_m430ia_support/meshes/m430ia/collision/base_link.stl"/>
      </geometry>
    </collision>
  </link>
<<<<<<< HEAD
=======

>>>>>>> 516daff7858fdc1e2262ddd0c2bcfce5399bf9be
  <link name="link_1">
    <visual>
      <origin rpy="0 0 0" xyz="0 0 0"/>
      <geometry>
        <mesh filename="package://fanuc_m430ia_support/meshes/m430ia/visual/link_1.stl"/>
      </geometry>
<<<<<<< HEAD
      <material name="">
        <color rgba="0.86 0.85 0.81 1.0"/>
      </material>
=======
      <material name="fanuc_grey"/>
>>>>>>> 516daff7858fdc1e2262ddd0c2bcfce5399bf9be
    </visual>
    <collision>
      <origin rpy="0 0 0" xyz="0 0 0"/>
      <geometry>
        <mesh filename="package://fanuc_m430ia_support/meshes/m430ia/collision/link_1.stl"/>
      </geometry>
    </collision>
  </link>
<<<<<<< HEAD
=======

>>>>>>> 516daff7858fdc1e2262ddd0c2bcfce5399bf9be
  <link name="link_2">
    <visual>
      <origin rpy="0 0 0" xyz="0 0 0"/>
      <geometry>
        <mesh filename="package://fanuc_m430ia_support/meshes/m430ia/visual/link_2.stl"/>
      </geometry>
<<<<<<< HEAD
      <material name="">
        <color rgba="0.86 0.85 0.81 1.0"/>
      </material>
=======
      <material name="fanuc_grey"/>
>>>>>>> 516daff7858fdc1e2262ddd0c2bcfce5399bf9be
    </visual>
    <collision>
      <origin rpy="0 0 0" xyz="0 0 0"/>
      <geometry>
        <mesh filename="package://fanuc_m430ia_support/meshes/m430ia/collision/link_2.stl"/>
      </geometry>
    </collision>
  </link>
<<<<<<< HEAD
=======

>>>>>>> 516daff7858fdc1e2262ddd0c2bcfce5399bf9be
  <link name="link_3">
    <visual>
      <origin rpy="0 0 0" xyz="0 0 0"/>
      <geometry>
        <mesh filename="package://fanuc_m430ia_support/meshes/m430ia/visual/link_3.stl"/>
      </geometry>
<<<<<<< HEAD
      <material name="">
        <color rgba="0.86 0.85 0.81 1.0"/>
      </material>
=======
      <material name="fanuc_grey"/>
>>>>>>> 516daff7858fdc1e2262ddd0c2bcfce5399bf9be
    </visual>
    <collision>
      <origin rpy="0 0 0" xyz="0 0 0"/>
      <geometry>
        <mesh filename="package://fanuc_m430ia_support/meshes/m430ia/collision/link_3.stl"/>
      </geometry>
    </collision>
  </link>
<<<<<<< HEAD
=======

>>>>>>> 516daff7858fdc1e2262ddd0c2bcfce5399bf9be
  <link name="link_4">
    <visual>
      <origin rpy="0 0 0" xyz="0 0 0"/>
      <geometry>
        <mesh filename="package://fanuc_m430ia_support/meshes/m430ia/visual/link_4.stl"/>
      </geometry>
<<<<<<< HEAD
      <material name="">
        <color rgba="0.86 0.85 0.81 1.0"/>
      </material>
=======
      <material name="fanuc_grey"/>
>>>>>>> 516daff7858fdc1e2262ddd0c2bcfce5399bf9be
    </visual>
    <collision>
      <origin rpy="0 0 0" xyz="0 0 0"/>
      <geometry>
        <mesh filename="package://fanuc_m430ia_support/meshes/m430ia/collision/link_4.stl"/>
      </geometry>
    </collision>
  </link>
<<<<<<< HEAD
=======

>>>>>>> 516daff7858fdc1e2262ddd0c2bcfce5399bf9be
  <link name="link_5">
    <visual>
      <origin rpy="0 0 0" xyz="0 0 0"/>
      <geometry>
        <mesh filename="package://fanuc_m430ia_support/meshes/m430ia/visual/link_5.stl"/>
      </geometry>
<<<<<<< HEAD
      <material name="">
        <color rgba="0.86 0.85 0.81 1.0"/>
      </material>
=======
      <material name="fanuc_grey"/>
>>>>>>> 516daff7858fdc1e2262ddd0c2bcfce5399bf9be
    </visual>
    <collision>
      <origin rpy="0 0 0" xyz="0 0 0"/>
      <geometry>
        <mesh filename="package://fanuc_m430ia_support/meshes/m430ia/collision/link_5.stl"/>
      </geometry>
    </collision>
  </link>
<<<<<<< HEAD
  <!-- joints: main serial chain -->
=======


  <!-- ~~~~~~~~~~~~~ JOINTS ~~~~~~~~~~~~~~ -->


>>>>>>> 516daff7858fdc1e2262ddd0c2bcfce5399bf9be
  <joint name="joint_1" type="revolute">
    <origin rpy="0 0 0" xyz="0 0 0.440"/>
    <parent link="base_link"/>
    <child link="link_1"/>
    <axis xyz="0 0 1"/>
    <limit effort="0" lower="-3.1415" upper="3.1415" velocity="5.24"/>
  </joint>
<<<<<<< HEAD
=======

>>>>>>> 516daff7858fdc1e2262ddd0c2bcfce5399bf9be
  <joint name="joint_2" type="revolute">
    <origin rpy="0 0 0" xyz="0 0 0"/>
    <parent link="link_1"/>
    <child link="link_2"/>
    <axis xyz="0 1 0"/>
    <limit effort="0" lower="-2.01" upper="2.01" velocity="5.59"/>
  </joint>
<<<<<<< HEAD
=======

>>>>>>> 516daff7858fdc1e2262ddd0c2bcfce5399bf9be
  <joint name="joint_3" type="revolute">
    <origin rpy="0 0 0" xyz="0 -0.095 0.350"/>
    <parent link="link_2"/>
    <child link="link_3"/>
    <axis xyz="0 1 0"/>
    <limit effort="0" lower="-3.34" upper="3.34" velocity="5.59"/>
  </joint>
<<<<<<< HEAD
=======

>>>>>>> 516daff7858fdc1e2262ddd0c2bcfce5399bf9be
  <joint name="joint_4" type="revolute">
    <origin rpy="0 0 0" xyz="0 0 0.550"/>
    <parent link="link_3"/>
    <child link="link_4"/>
    <axis xyz="0 1 0"/>
    <limit effort="0" lower="-2.62" upper="2.62" velocity="6.28"/>
  </joint>
<<<<<<< HEAD
=======

>>>>>>> 516daff7858fdc1e2262ddd0c2bcfce5399bf9be
  <joint name="joint_5" type="revolute">
    <origin rpy="0 0 0" xyz="0 0 0.065"/>
    <parent link="link_4"/>
    <child link="link_5"/>
    <axis xyz="0 0 1"/>
    <limit effort="0" lower="-4.71" upper="4.71" velocity="20.94"/>
  </joint>
<<<<<<< HEAD
  <!-- ROS-Industrial 'base' frame: base_link to Fanuc World Coordinates transform -->
=======


  <!-- ~~~~~~~~~~~~~ CONNECT ~~~~~~~~~~~~~ -->


  <!-- Base link to work frame --> 
>>>>>>> 516daff7858fdc1e2262ddd0c2bcfce5399bf9be
  <link name="base"/>
  <joint name="base_link-base" type="fixed">
    <origin rpy="0 0 0" xyz="0 0 0.440"/>
    <parent link="base_link"/>
    <child link="base"/>
  </joint>
<<<<<<< HEAD
  <!-- ROS-Industrial 'flange' frame: attachment point for EEF models -->
=======

  <!-- Flange attachment point for EEF models --> 
>>>>>>> 516daff7858fdc1e2262ddd0c2bcfce5399bf9be
  <link name="flange"/>
  <joint name="joint_5-flange" type="fixed">
    <origin rpy="0 -1.5707963267948966 0" xyz="0 0 0"/>
    <parent link="link_5"/>
    <child link="flange"/>
  </joint>
<<<<<<< HEAD
  <!-- ROS-Industrial 'tool0' frame: all-zeros tool frame -->
  <link name="tool0"/>
  <!-- Note: instead of 'flange', we use 'link_5' as parent of this frame
               as it already has the correct orientation and location for
               'tool0'. Using 'flange' here would require additional rotations
               to undo the rotation introduced by 'joint_5-flange'.
     -->
=======

  <!-- Tool for all-zeros frame -->
  <link name="tool0"/>

  <!-- Used instead of flange becuase link is already in correct orientation and location -->
>>>>>>> 516daff7858fdc1e2262ddd0c2bcfce5399bf9be
  <joint name="link_5-tool0" type="fixed">
    <origin rpy="0 0 0" xyz="0 0 0"/>
    <parent link="link_5"/>
    <child link="tool0"/>
  </joint>
</robot>