<?xml version="1.0"?>
<robot name="fanuc_m430ia" xmlns:xacro="http://wiki.ros.org/xacro">
  <xacro:include filename="$(find fanuc_resources)/urdf/common_materials.xacro"/>

  <xacro:macro name="fanuc_m430ia" params="prefix">


    <!-- ~~~~~~~~~~~~~~ LINKS ~~~~~~~~~~~~~~ -->


    <link name="${prefix}base_link">
      <visual>
        <origin xyz="0 0 0" rpy="0 0 0"/>
        <geometry>
          <mesh filename="package://fanuc_m430ia_support/meshes/m430ia/visual/base.stl" scale="0.1 0.1 0.1"/>
        </geometry>
        <xacro:material_fanuc_white />
      </visual>
      <collision>
        <origin xyz="0 0 0" rpy="0 0 0"/>
        <geometry>
          <mesh filename="package://fanuc_m430ia_support/meshes/m430ia/collision/base.stl" scale="0.1 0.1 0.1"/>
        </geometry>
      </collision>
    </link>

    <link name="${prefix}link_1">
      <visual>
        <origin xyz="0 0 0" rpy="0 0 0"/>
        <geometry>
          <mesh filename="package://fanuc_m430ia_support/meshes/m430ia/visual/link_1.stl"/>
        </geometry>
        <xacro:material_fanuc_white />
      </visual>
      <collision>
        <origin xyz="0 0 0" rpy="0 0 0"/>
        <geometry>
          <mesh filename="package://fanuc_m430ia_support/meshes/m430ia/collision/link_1.stl"/>
        </geometry>
      </collision>
    </link>

    <link name="${prefix}link_2">
      <visual>
        <origin xyz="0 0 0" rpy="0 0 0"/>
        <geometry>
          <mesh filename="package://fanuc_m430ia_support/meshes/m430ia/visual/link_2.stl"/>
        </geometry>
        <xacro:material_fanuc_white />
      </visual>
      <collision>
        <origin xyz="0 0 0" rpy="0 0 0"/>
        <geometry>
          <mesh filename="package://fanuc_m430ia_support/meshes/m430ia/collision/link_2.stl"/>
        </geometry>
      </collision>
    </link>

    <link name="${prefix}link_3">
      <visual>
        <origin xyz="0 0 0" rpy="0 0 0"/>
        <geometry>
          <mesh filename="package://fanuc_m430ia_support/meshes/m430ia/visual/link_3.stl" scale="0.1 0.1 0.1"/>
        </geometry>
        <xacro:material_fanuc_white />
      </visual>
      <collision>
        <origin xyz="0 0 0" rpy="0 0 0"/>
        <geometry>
          <mesh filename="package://fanuc_m430ia_support/meshes/m430ia/collision/link_3.stl" scale="0.1 0.1 0.1"/>
        </geometry>
      </collision>
    </link>

    <link name="${prefix}link_4">
      <visual>
        <origin xyz="0 0 0" rpy="0 0 0"/>
        <geometry>
          <mesh filename="package://fanuc_m430ia_support/meshes/m430ia/visual/link_4.stl"/>
        </geometry>
        <xacro:material_fanuc_white />
      </visual>
      <collision>
        <origin xyz="0 0 0" rpy="0 0 0"/>
        <geometry>
          <mesh filename="package://fanuc_m430ia_support/meshes/m430ia/collision/link_4.stl"/>
        </geometry>
      </collision>
    </link>

    <link name="${prefix}link_5">
      <visual>
        <origin xyz="0 0 0" rpy="0 0 0"/>
        <geometry>
          <mesh filename="package://fanuc_m430ia_support/meshes/m430ia/visual/link_5.stl"/>
        </geometry>
        <xacro:material_fanuc_white />
      </visual>
      <collision>
        <origin xyz="0 0 0" rpy="0 0 0"/>
        <geometry>
          <mesh filename="package://fanuc_m430ia_support/meshes/m430ia/collision/link_5.stl"/>
        </geometry>
      </collision>
    </link>


    <!-- ~~~~~~~~~~~~~ JOINTS ~~~~~~~~~~~~~~ -->


    <joint name="${prefix}joint_1" type="revolute">
      <limit lower="-3.1415" upper="3.1415" effort="0" velocity="5.24"/>
      <origin rpy="0 0 0" xyz="0 0 0.475"/>
      <parent link="${prefix}base_link"/>
      <child link="${prefix}link_1"/>
      <axis xyz="0 0 1"/>
    </joint>

    <joint name="${prefix}joint_2" type="revolute">
      <limit lower="-2.01" upper="2.01" effort="0" velocity="5.59"/>
      <origin rpy="0 0 0" xyz="0 0 0"/>
      <parent link="${prefix}link_1"/>
      <child link="${prefix}link_2"/>
      <axis xyz="0 1 0"/>
    </joint>

    <joint name="${prefix}joint_3" type="revolute">
      <limit lower="-3.34" upper="3.34" effort="0" velocity="5.59"/>
      <origin rpy="0 0 0" xyz="0 -0.095 0.350"/>
      <parent link="${prefix}link_2"/>
      <child link="${prefix}link_3"/>
      <axis xyz="0 1 0"/>
    </joint>

    <joint name="${prefix}joint_4" type="revolute">
      <limit lower="-2.62" upper="2.62" effort="0" velocity="6.28"/>
      <origin rpy="0 0 0" xyz="0 0 0.550"/>
      <parent link="${prefix}link_3"/>
      <child link="${prefix}link_4"/>
      <axis xyz="0 1 0"/>
    </joint>

    <joint name="${prefix}joint_5" type="revolute">
      <limit lower="-4.71" upper="4.71" effort="0" velocity="20.94"/>
      <origin rpy="0 0 0" xyz="0 0 0.065"/>
      <parent link="${prefix}link_4"/>
      <child link="${prefix}link_5"/>
      <axis xyz="0 0 1"/>
    </joint>


    <!-- ~~~~~~~~~~~~~ CONNECT ~~~~~~~~~~~~~ -->

    <!-- Base link to work frame --> 
    <link name="base"/>

    <joint name="base_link-base" type="fixed">
      <origin rpy="0 0 0" xyz="0 0 0.475"/>
      <parent link="base_link"/>
      <child link="base"/>
    </joint>

    <!-- Flange attachment point for EEF models --> 
    <link name="flange"/>

    <joint name="joint_5-flange" type="fixed">
      <origin rpy="0 -1.5707963267948966 0" xyz="0 0 0"/>
      <parent link="link_5"/>
      <child link="flange"/>
    </joint>

    <!-- Tool for all-zeros frame -->
    <link name="tool0"/>

    <!-- Used instead of flange becuase link is already in correct orientation and location -->
    <joint name="link_5-tool0" type="fixed">
      <origin rpy="0 0 0" xyz="0 0 0"/>
      <parent link="link_5"/>
      <child link="tool0"/>
    </joint>


    <!-- ~~~~~~~~~~~ END EFFECTOR ~~~~~~~~~~ -->


    <link name="ee_base">
      <visual>
        <origin rpy="0 1.5708 0" xyz="0 0 0"/>
        <geometry>
          <mesh filename="package://fanuc_m430ia_support/meshes/gripper/end_effector.stl" scale="0.001 0.001 0.001"/>
        </geometry>
        <xacro:material_fanuc_white />
      </visual>
      <collision>
        <origin rpy="0 1.5708 0" xyz="0 0 0"/>
        <geometry>
          <mesh filename="package://fanuc_m430ia_support/meshes/gripper/end_effector.stl" scale="0.001 0.001 0.001"/>
        </geometry>
      </collision>
    </link>

    <joint name="ee_base" type="fixed">
      <origin rpy="0 0 0" xyz="0 0 0"/>
      <parent link="flange"/>
      <child link="ee_base"/>
    </joint>

    <link name="left_finger">
      <visual>
        <origin rpy="-1.5708 0 -1.5708" xyz="0.015 0 0.01"/> 
        <geometry>
          <mesh filename="package://fanuc_m430ia_support/meshes/gripper/finger.stl" scale="0.001 0.001 0.001"/>
        </geometry>
        <xacro:material_fanuc_white />
      </visual>
      <collision>
        <origin rpy="-1.5708 0 -1.5708" xyz="0.015 0 0.01"/> 
        <geometry>
          <mesh filename="package://fanuc_m430ia_support/meshes/gripper/finger.stl" scale="0.001 0.001 0.001"/>
        </geometry>
      </collision>
    </link>

    <joint name="left_finger" type="prismatic">
      <limit lower="-0.005" upper="0.02" effort="0" velocity="5"/>
      <origin rpy="0 0 0" xyz="0 0 0"/>
      <parent link="ee_base"/>
      <child link="left_finger"/>
      <axis xyz="0 0 1"/>
    </joint>


    <link name="right_finger">
      <visual>
        <origin rpy="1.5708 0 1.5708" xyz="0.015 0 -0.01"/> 
        <geometry>
          <mesh filename="package://fanuc_m430ia_support/meshes/gripper/finger.stl" scale="0.001 0.001 0.001"/>
        </geometry>
        <xacro:material_fanuc_white />
      </visual>
      <collision>
        <origin rpy="1.5708 0 1.5708" xyz="0.015 0 -0.01"/> 
        <geometry>
          <mesh filename="package://fanuc_m430ia_support/meshes/gripper/finger.stl" scale="0.001 0.001 0.001"/>
        </geometry>
      </collision>
    </link>

    <joint name="right_finger" type="prismatic">
      <limit lower="-0.02" upper="0.005" effort="0" velocity="5"/>
      <origin rpy="0 0 0" xyz="0 0 0"/>
      <parent link="ee_base"/>
      <child link="right_finger"/>
      <axis xyz="0 0 1"/>
    </joint>

  </xacro:macro>
</robot>
